<robot name="two_wheel_robot">

    <!-- Define materials -->
    <material name="gray">
        <color rgba="0.5 0.5 0.5 1.0"/> <!-- RGB + Alpha for transparency -->
    </material>
    <material name="black">
        <color rgba="0.0 0.0 0.0 1.0"/> <!-- RGB + Alpha for transparency -->
    </material>
    <material name="blue">
        <color rgba="0.0 0.0 1.0 1.0"/> <!-- RGB + Alpha for transparency -->
    </material>

    <!-- Base Link -->
    <link name="base_link">
        <visual>
            <geometry>
                <box size="0.5 0.3 0.1"/> <!-- Width x Depth x Height -->
            </geometry>
            <material name="gray"/>
        </visual>
        <collision>
            <geometry>
                <box size="0.5 0.3 0.1"/>
            </geometry>
        </collision>
        <inertial>
            <mass value="5.0"/>
            <origin xyz="0 0 0"/>
            <inertia ixx="0.1" ixy="0.0" ixz="0.0" iyy="0.1" iyz="0.0" izz="0.1"/>
        </inertial>
    </link>

    <!-- Left Wheel -->
    <link name="left_wheel">
        <visual>
            <geometry>
                <cylinder length="0.02" radius="0.1"/>
            </geometry>
            <material name="black"/>
        </visual>
        <collision>
            <geometry>
                <cylinder length="0.02" radius="0.1"/>
            </geometry>
        </collision>
        <inertial>
            <mass value="1.0"/>
            <origin xyz="0 0 0"/>
            <inertia ixx="0.01" ixy="0.0" ixz="0.0" iyy="0.01" iyz="0.0" izz="0.01"/>
        </inertial>
    </link>

    <joint name="left_wheel_joint" type="continuous">
        <parent link="base_link"/>
        <child link="left_wheel"/>
        <origin xyz="-0.2 0.15 -0.05" rpy="0 0 0"/> <!-- Position relative to base_link -->
        <axis xyz="0 1 0"/>
    </joint>

    <!-- Right Wheel -->
    <link name="right_wheel">
        <visual>
            <geometry>
                <cylinder length="0.02" radius="0.1"/>
            </geometry>
            <material name="black"/>
        </visual>
        <collision>
            <geometry>
                <cylinder length="0.02" radius="0.1"/>
            </geometry>
        </collision>
        <inertial>
            <mass value="1.0"/>
            <origin xyz="0 0 0"/>
            <inertia ixx="0.01" ixy="0.0" ixz="0.0" iyy="0.01" iyz="0.0" izz="0.01"/>
        </inertial>
    </link>

    <joint name="right_wheel_joint" type="continuous">
        <parent link="base_link"/>
        <child link="right_wheel"/>
        <origin xyz="-0.2 -0.15 -0.05" rpy="0 0 0"/> <!-- Position relative to base_link -->
        <axis xyz="0 1 0"/>
    </joint>

    <!-- Camera Link -->
    <link name="camera_link">
        <visual>
            <geometry>
                <box size="0.1 0.1 0.1"/>
            </geometry>
            <material name="blue"/>
        </visual>
        <collision>
            <geometry>
                <box size="0.1 0.1 0.1"/>
            </geometry>
        </collision>
        <inertial>
            <mass value="0.5"/>
            <origin xyz="0 0 0"/>
            <inertia ixx="0.001" ixy="0.0" ixz="0.0" iyy="0.001" iyz="0.0" izz="0.001"/>
        </inertial>
    </link>

    <joint name="camera_joint" type="fixed">
        <parent link="base_link"/>
        <child link="camera_link"/>
        <origin xyz="0 0 0.2" rpy="0 0 0"/> <!-- Camera position on top of the base -->
    </joint>

    <!-- Camera Sensor -->
    <gazebo reference="camera_link">
        <sensor type="camera" name="camera">
            <camera>
                <horizontal_fov>1.047</horizontal_fov>
                <image>
                    <width>640</width>
                    <height>480</height>
                    <format>R8G8B8</format>
                </image>
                <clip>
                    <near>0.1</near>
                    <far>100</far>
                </clip>
            </camera>
            <always_on>true</always_on>
            <update_rate>30</update_rate>
            <visualize>true</visualize>
            <plugin name="camera_controller" filename="libgazebo_ros_camera.so">
                <always_on>true</always_on>
                <update_rate>30.0</update_rate>
                <camera_name>camera</camera_name>
                <image_topic_name>image_raw</image_topic_name>
                <camera_info_topic_name>camera_info</camera_info_topic_name>
            </plugin>
        </sensor>
    </gazebo>
</robot>
